
const findUserByIdController = async (req, res) => {
    try {

    } catch (err) {
        console.log(`erro: ${err.message}`);
        return res.status(500).send({ message: `Erro inesperado, tente novamente.` });
    }
}

const findAllUsersController = async (req, res) => {
    try {

    } catch (err) {
        console.log(`erro: ${err.message}`);
        return res.status(500).send({ message: `Erro inesperado, tente novamente.` });
    }
}

const createUserController = async (req, res) => {
    try {

    } catch (err) {
        console.log(`erro: ${err.message}`);
        return res.status(500).send({ message: `Erro inesperado, tente novamente.` });
    }
}

const updateUserController = async (req, res) => {
    try {

    } catch (err) {
        console.log(`erro: ${err.message}`);
        return res.status(500).send({ message: `Erro inesperado, tente novamente.` });
    }
}

const removeUserController = async (req, res) => {
    try {

    } catch (err) {
        console.log(`erro: ${err.message}`);
        return res.status(500).send({ message: `Erro inesperado, tente novamente.` });
    }
}

const addUserAddressController = async (req, res) => {
    try {

    } catch (err) {
        console.log(`erro: ${err.message}`);
        return res.status(500).send({ message: `Erro inesperado, tente novamente.` });
    }
}

const removeUserAddressController = async (req, res) => {
    try {

    } catch (err) {
        console.log(`erro: ${err.message}`);
        return res.status(500).send({ message: `Erro inesperado, tente novamente.` });
    }
}

const addUserFavPizza = async (req, res) => {
    try {

    } catch (err) {
        console.log(`erro: ${err.message}`);
        return res.status(500).send({ message: `Erro inesperado, tente novamente.` });
    }
}

const removeUserFavPizza = async (req, res) => {
    try {

    } catch (err) {
        console.log(`erro: ${err.message}`);
        return res.status(500).send({ message: `Erro inesperado, tente novamente.` });
    }
}

const addUserFavBebida = async (req, res) => {
    try {

    } catch (err) {
        console.log(`erro: ${err.message}`);
        return res.status(500).send({ message: `Erro inesperado, tente novamente.` });
    }
}

const removeUserFavBebida = async (req, res) => {
    try {

    } catch (err) {
        console.log(`erro: ${err.message}`);
        return res.status(500).send({ message: `Erro inesperado, tente novamente.` });
    }
}

module.exports = {
    findUserByIdController,
    findAllUsersController,
    createUserController,
    updateUserController,
    removeUserController,
    addUserAddressController,
    removeUserAddressController,
    addUserFavPizza,
    removeUserFavPizza,
    addUserFavBebida,
    removeUserFavBebida
}